<?xml version="1.0" encoding="UTF-8"?>
<mujoco model="rickshaw">
  <compiler angle="radian" autolimits="true" />
  <option gravity="0 0 -9.81" />

  <asset>
    <mesh name="body_visual" file="assets/body.stl" scale="0.0001 0.0001 0.0001" />
    <mesh name="left_wheel_visual" file="assets/right_wheel.stl" scale="0.0001 0.00008 0.00008" />
    <mesh name="right_wheel_visual" file="assets/left_wheel.stl" scale="0.0001 0.00008 0.00008" />
    <material name="body_dark_red" rgba="0.18 0.004 0.008 1" />
    <material name="wheel_dark" rgba="0.05 0.05 0.05 1" />
  </asset>

  <worldbody>
    <body name="base_link">
      <freejoint name="floating_base_joint" />
      <inertial pos="0.1 0 0.6276898532066667" mass="30" fullinertia="6.16 18.5 14.86 0 0 0" />
      <geom name="body_visual" type="mesh" mesh="body_visual"
        pos="1.94034 -0.414504 -0.074999" euler="0 0 1.57079632679"
        material="body_dark_red" contype="0" conaffinity="0" />

      <site name="left_tow_hitch" pos="1.85049373 0.235 0.18164719" size="0.015" rgba="0.9 0.2 0.1 1" />
      <site name="right_tow_hitch" pos="1.85049373 -0.235 0.18164719" size="0.015" rgba="0.9 0.2 0.1 1" />

      <body name="left_wheel_link" pos="0 0.378231 0.3">
        <joint name="left_wheel_joint" type="hinge" axis="0 1 0" damping="0.02" />
        <inertial pos="0 0 0" mass="2" diaginertia="0.04587720205066667 0.09 0.04587720205066667" />
        <geom name="left_wheel_visual" type="mesh" mesh="left_wheel_visual"
          pos="1.552272 -0.792735 -0.3" euler="0 0 1.57079632679"
          material="wheel_dark" contype="0" conaffinity="0" />
        <geom name="left_wheel_collision" type="cylinder" size="0.3 0.036274"
          quat="0.7071067811865476 0.7071067811865476 0 0"
          friction="1.0 0.01 0.001" condim="6" group="3" rgba="0 0 0 0" />
      </body>

      <body name="right_wheel_link" pos="0 -0.378231 0.3">
        <joint name="right_wheel_joint" type="hinge" axis="0 1 0" damping="0.02" />
        <inertial pos="0 0 0" mass="2" diaginertia="0.04587720205066667 0.09 0.04587720205066667" />
        <geom name="right_wheel_visual" type="mesh" mesh="right_wheel_visual"
          pos="1.552272 -0.036274 -0.3" euler="0 0 1.57079632679"
          material="wheel_dark" contype="0" conaffinity="0" />
        <geom name="right_wheel_collision" type="cylinder" size="0.3 0.036274"
          quat="0.7071067811865476 0.7071067811865476 0 0"
          friction="1.0 0.01 0.001" condim="6" group="3" rgba="0 0 0 0" />
      </body>
    </body>
  </worldbody>
</mujoco>
